
  You can now view your Streamlit app in your browser.

  URL: http://0.0.0.0:3000

Exception in callback AppSession._on_scriptrunner_event.<locals>.<lambda>() at /usr/local/lib/python3.12/site-packages/streamlit/runtime/app_session.py:470
handle: <Handle AppSession._on_scriptrunner_event.<locals>.<lambda>() at /usr/local/lib/python3.12/site-packages/streamlit/runtime/app_session.py:470>
Traceback (most recent call last):
  File "/usr/local/lib/python3.12/asyncio/events.py", line 88, in _run
    self._context.run(self._callback, *self._args)
  File "/usr/local/lib/python3.12/site-packages/streamlit/runtime/app_session.py", line 470, in <lambda>
    lambda: self._handle_scriptrunner_event_on_event_loop(
            ^^^^^^^^^^^^^^^^^^^^^^^^^^^^^^^^^^^^^^^^^^^^^^
  File "/usr/local/lib/python3.12/site-packages/streamlit/runtime/app_session.py", line 540, in _handle_scriptrunner_event_on_event_loop
    self._create_new_session_message(page_script_hash)
  File "/usr/local/lib/python3.12/site-packages/streamlit/runtime/app_session.py", line 646, in _create_new_session_message
    _populate_user_info_msg(imsg.user_info)
  File "/usr/local/lib/python3.12/site-packages/streamlit/runtime/app_session.py", line 866, in _populate_user_info_msg
    msg.installation_id = Installation.instance().installation_id
                          ^^^^^^^^^^^^^^^^^^^^^^^
  File "/usr/local/lib/python3.12/site-packages/streamlit/runtime/metrics_util.py", line 186, in instance
    cls._instance = Installation()
                    ^^^^^^^^^^^^^^
  File "/usr/local/lib/python3.12/site-packages/streamlit/runtime/metrics_util.py", line 191, in __init__
    uuid.uuid5(uuid.NAMESPACE_DNS, _get_machine_id_v3())
                                   ^^^^^^^^^^^^^^^^^^^^
  File "/usr/local/lib/python3.12/site-packages/streamlit/runtime/metrics_util.py", line 164, in _get_machine_id_v3
    machine_id = f.read()
                 ^^^^^^^^
  File "<frozen codecs>", line 322, in decode
UnicodeDecodeError: 'utf-8' codec can't decode bytes in position 25-26: invalid continuation byte
Exception in callback AppSession._on_scriptrunner_event.<locals>.<lambda>() at /usr/local/lib/python3.12/site-packages/streamlit/runtime/app_session.py:470
handle: <Handle AppSession._on_scriptrunner_event.<locals>.<lambda>() at /usr/local/lib/python3.12/site-packages/streamlit/runtime/app_session.py:470>
Traceback (most recent call last):
  File "/usr/local/lib/python3.12/asyncio/events.py", line 88, in _run
    self._context.run(self._callback, *self._args)
  File "/usr/local/lib/python3.12/site-packages/streamlit/runtime/app_session.py", line 470, in <lambda>
    lambda: self._handle_scriptrunner_event_on_event_loop(
            ^^^^^^^^^^^^^^^^^^^^^^^^^^^^^^^^^^^^^^^^^^^^^^
  File "/usr/local/lib/python3.12/site-packages/streamlit/runtime/app_session.py", line 540, in _handle_scriptrunner_event_on_event_loop
    self._create_new_session_message(page_script_hash)
  File "/usr/local/lib/python3.12/site-packages/streamlit/runtime/app_session.py", line 646, in _create_new_session_message
    _populate_user_info_msg(imsg.user_info)
  File "/usr/local/lib/python3.12/site-packages/streamlit/runtime/app_session.py", line 866, in _populate_user_info_msg
    msg.installation_id = Installation.instance().installation_id
                          ^^^^^^^^^^^^^^^^^^^^^^^
  File "/usr/local/lib/python3.12/site-packages/streamlit/runtime/metrics_util.py", line 186, in instance
    cls._instance = Installation()
                    ^^^^^^^^^^^^^^
  File "/usr/local/lib/python3.12/site-packages/streamlit/runtime/metrics_util.py", line 191, in __init__
    uuid.uuid5(uuid.NAMESPACE_DNS, _get_machine_id_v3())
                                   ^^^^^^^^^^^^^^^^^^^^
  File "/usr/local/lib/python3.12/site-packages/streamlit/runtime/metrics_util.py", line 164, in _get_machine_id_v3
    machine_id = f.read()
                 ^^^^^^^^
  File "<frozen codecs>", line 322, in decode
UnicodeDecodeError: 'utf-8' codec can't decode bytes in position 25-26: invalid continuation byte
Exception in callback AppSession._on_scriptrunner_event.<locals>.<lambda>() at /usr/local/lib/python3.12/site-packages/streamlit/runtime/app_session.py:470
handle: <Handle AppSession._on_scriptrunner_event.<locals>.<lambda>() at /usr/local/lib/python3.12/site-packages/streamlit/runtime/app_session.py:470>
Traceback (most recent call last):
  File "/usr/local/lib/python3.12/asyncio/events.py", line 88, in _run
    self._context.run(self._callback, *self._args)
  File "/usr/local/lib/python3.12/site-packages/streamlit/runtime/app_session.py", line 470, in <lambda>
    lambda: self._handle_scriptrunner_event_on_event_loop(
            ^^^^^^^^^^^^^^^^^^^^^^^^^^^^^^^^^^^^^^^^^^^^^^
  File "/usr/local/lib/python3.12/site-packages/streamlit/runtime/app_session.py", line 540, in _handle_scriptrunner_event_on_event_loop
    self._create_new_session_message(page_script_hash)
  File "/usr/local/lib/python3.12/site-packages/streamlit/runtime/app_session.py", line 646, in _create_new_session_message
    _populate_user_info_msg(imsg.user_info)
  File "/usr/local/lib/python3.12/site-packages/streamlit/runtime/app_session.py", line 866, in _populate_user_info_msg
    msg.installation_id = Installation.instance().installation_id
                          ^^^^^^^^^^^^^^^^^^^^^^^
  File "/usr/local/lib/python3.12/site-packages/streamlit/runtime/metrics_util.py", line 186, in instance
    cls._instance = Installation()
                    ^^^^^^^^^^^^^^
  File "/usr/local/lib/python3.12/site-packages/streamlit/runtime/metrics_util.py", line 191, in __init__
    uuid.uuid5(uuid.NAMESPACE_DNS, _get_machine_id_v3())
                                   ^^^^^^^^^^^^^^^^^^^^
  File "/usr/local/lib/python3.12/site-packages/streamlit/runtime/metrics_util.py", line 164, in _get_machine_id_v3
    machine_id = f.read()
                 ^^^^^^^^
  File "<frozen codecs>", line 322, in decode
UnicodeDecodeError: 'utf-8' codec can't decode bytes in position 25-26: invalid continuation byte
Exception in callback AppSession._on_scriptrunner_event.<locals>.<lambda>() at /usr/local/lib/python3.12/site-packages/streamlit/runtime/app_session.py:470
handle: <Handle AppSession._on_scriptrunner_event.<locals>.<lambda>() at /usr/local/lib/python3.12/site-packages/streamlit/runtime/app_session.py:470>
Traceback (most recent call last):
  File "/usr/local/lib/python3.12/asyncio/events.py", line 88, in _run
    self._context.run(self._callback, *self._args)
  File "/usr/local/lib/python3.12/site-packages/streamlit/runtime/app_session.py", line 470, in <lambda>
    lambda: self._handle_scriptrunner_event_on_event_loop(
            ^^^^^^^^^^^^^^^^^^^^^^^^^^^^^^^^^^^^^^^^^^^^^^
  File "/usr/local/lib/python3.12/site-packages/streamlit/runtime/app_session.py", line 540, in _handle_scriptrunner_event_on_event_loop
    self._create_new_session_message(page_script_hash)
  File "/usr/local/lib/python3.12/site-packages/streamlit/runtime/app_session.py", line 646, in _create_new_session_message
    _populate_user_info_msg(imsg.user_info)
  File "/usr/local/lib/python3.12/site-packages/streamlit/runtime/app_session.py", line 866, in _populate_user_info_msg
    msg.installation_id = Installation.instance().installation_id
                          ^^^^^^^^^^^^^^^^^^^^^^^
  File "/usr/local/lib/python3.12/site-packages/streamlit/runtime/metrics_util.py", line 186, in instance
    cls._instance = Installation()
                    ^^^^^^^^^^^^^^
  File "/usr/local/lib/python3.12/site-packages/streamlit/runtime/metrics_util.py", line 191, in __init__
    uuid.uuid5(uuid.NAMESPACE_DNS, _get_machine_id_v3())
                                   ^^^^^^^^^^^^^^^^^^^^
  File "/usr/local/lib/python3.12/site-packages/streamlit/runtime/metrics_util.py", line 164, in _get_machine_id_v3
    machine_id = f.read()
                 ^^^^^^^^
  File "<frozen codecs>", line 322, in decode
UnicodeDecodeError: 'utf-8' codec can't decode bytes in position 25-26: invalid continuation byte
Exception in callback AppSession._on_scriptrunner_event.<locals>.<lambda>() at /usr/local/lib/python3.12/site-packages/streamlit/runtime/app_session.py:470
handle: <Handle AppSession._on_scriptrunner_event.<locals>.<lambda>() at /usr/local/lib/python3.12/site-packages/streamlit/runtime/app_session.py:470>
Traceback (most recent call last):
  File "/usr/local/lib/python3.12/asyncio/events.py", line 88, in _run
    self._context.run(self._callback, *self._args)
  File "/usr/local/lib/python3.12/site-packages/streamlit/runtime/app_session.py", line 470, in <lambda>
    lambda: self._handle_scriptrunner_event_on_event_loop(
            ^^^^^^^^^^^^^^^^^^^^^^^^^^^^^^^^^^^^^^^^^^^^^^
  File "/usr/local/lib/python3.12/site-packages/streamlit/runtime/app_session.py", line 540, in _handle_scriptrunner_event_on_event_loop
    self._create_new_session_message(page_script_hash)
  File "/usr/local/lib/python3.12/site-packages/streamlit/runtime/app_session.py", line 646, in _create_new_session_message
    _populate_user_info_msg(imsg.user_info)
  File "/usr/local/lib/python3.12/site-packages/streamlit/runtime/app_session.py", line 866, in _populate_user_info_msg
    msg.installation_id = Installation.instance().installation_id
                          ^^^^^^^^^^^^^^^^^^^^^^^
  File "/usr/local/lib/python3.12/site-packages/streamlit/runtime/metrics_util.py", line 186, in instance
    cls._instance = Installation()
                    ^^^^^^^^^^^^^^
  File "/usr/local/lib/python3.12/site-packages/streamlit/runtime/metrics_util.py", line 191, in __init__
    uuid.uuid5(uuid.NAMESPACE_DNS, _get_machine_id_v3())
                                   ^^^^^^^^^^^^^^^^^^^^
  File "/usr/local/lib/python3.12/site-packages/streamlit/runtime/metrics_util.py", line 164, in _get_machine_id_v3
    machine_id = f.read()
                 ^^^^^^^^
  File "<frozen codecs>", line 322, in decode
UnicodeDecodeError: 'utf-8' codec can't decode bytes in position 25-26: invalid continuation byte
